2021-10-02 15:53:33,093 - werkzeug - INFO -  * Running on http://127.0.0.1:5000/ (Press CTRL+C to quit)
2021-10-02 15:53:42,822 - werkzeug - INFO - 127.0.0.1 - - [02/Oct/2021 15:53:42] "GET / HTTP/1.1" 200 -
2021-10-02 15:53:43,031 - werkzeug - INFO - 127.0.0.1 - - [02/Oct/2021 15:53:43] "[33mGET /favicon.ico HTTP/1.1[0m" 404 -
2021-10-02 15:53:45,002 - werkzeug - INFO - 127.0.0.1 - - [02/Oct/2021 15:53:45] "GET /job HTTP/1.1" 200 -
2021-10-02 15:53:46,859 - werkzeug - INFO - 127.0.0.1 - - [02/Oct/2021 15:53:46] "GET /addjob HTTP/1.1" 200 -
2021-10-02 15:53:52,364 - werkzeug - INFO - 127.0.0.1 - - [02/Oct/2021 15:53:52] "POST /addjob HTTP/1.1" 200 -
2021-10-02 15:55:46,291 - werkzeug - INFO - 127.0.0.1 - - [02/Oct/2021 15:55:46] "GET /addjob HTTP/1.1" 200 -
2021-10-02 15:56:06,588 - werkzeug - INFO - 127.0.0.1 - - [02/Oct/2021 15:56:06] "POST /addjob HTTP/1.1" 200 -
2021-10-02 16:00:16,438 - werkzeug - INFO - 127.0.0.1 - - [02/Oct/2021 16:00:16] "GET /addjob HTTP/1.1" 200 -
2021-10-02 16:00:27,739 - werkzeug - INFO - 127.0.0.1 - - [02/Oct/2021 16:00:27] "POST /addjob HTTP/1.1" 200 -
2021-10-02 16:04:01,896 - werkzeug - INFO - 127.0.0.1 - - [02/Oct/2021 16:04:01] "GET /addjob HTTP/1.1" 200 -
2021-10-02 16:04:11,455 - webapp - ERROR - Exception on /addjob [POST]
Traceback (most recent call last):
  File "/Library/Frameworks/Python.framework/Versions/3.9/lib/python3.9/site-packages/urllib3/connection.py", line 159, in _new_conn
    conn = connection.create_connection(
  File "/Library/Frameworks/Python.framework/Versions/3.9/lib/python3.9/site-packages/urllib3/util/connection.py", line 84, in create_connection
    raise err
  File "/Library/Frameworks/Python.framework/Versions/3.9/lib/python3.9/site-packages/urllib3/util/connection.py", line 74, in create_connection
    sock.connect(sa)
ConnectionRefusedError: [Errno 61] Connection refused

During handling of the above exception, another exception occurred:

Traceback (most recent call last):
  File "/Library/Frameworks/Python.framework/Versions/3.9/lib/python3.9/site-packages/urllib3/connectionpool.py", line 670, in urlopen
    httplib_response = self._make_request(
  File "/Library/Frameworks/Python.framework/Versions/3.9/lib/python3.9/site-packages/urllib3/connectionpool.py", line 392, in _make_request
    conn.request(method, url, **httplib_request_kw)
  File "/Library/Frameworks/Python.framework/Versions/3.9/lib/python3.9/http/client.py", line 1255, in request
    self._send_request(method, url, body, headers, encode_chunked)
  File "/Library/Frameworks/Python.framework/Versions/3.9/lib/python3.9/http/client.py", line 1301, in _send_request
    self.endheaders(body, encode_chunked=encode_chunked)
  File "/Library/Frameworks/Python.framework/Versions/3.9/lib/python3.9/http/client.py", line 1250, in endheaders
    self._send_output(message_body, encode_chunked=encode_chunked)
  File "/Library/Frameworks/Python.framework/Versions/3.9/lib/python3.9/http/client.py", line 1010, in _send_output
    self.send(msg)
  File "/Library/Frameworks/Python.framework/Versions/3.9/lib/python3.9/http/client.py", line 950, in send
    self.connect()
  File "/Library/Frameworks/Python.framework/Versions/3.9/lib/python3.9/site-packages/urllib3/connection.py", line 187, in connect
    conn = self._new_conn()
  File "/Library/Frameworks/Python.framework/Versions/3.9/lib/python3.9/site-packages/urllib3/connection.py", line 171, in _new_conn
    raise NewConnectionError(
urllib3.exceptions.NewConnectionError: <urllib3.connection.HTTPConnection object at 0x7fa1e0083d90>: Failed to establish a new connection: [Errno 61] Connection refused

During handling of the above exception, another exception occurred:

Traceback (most recent call last):
  File "/Library/Frameworks/Python.framework/Versions/3.9/lib/python3.9/site-packages/requests/adapters.py", line 439, in send
    resp = conn.urlopen(
  File "/Library/Frameworks/Python.framework/Versions/3.9/lib/python3.9/site-packages/urllib3/connectionpool.py", line 726, in urlopen
    retries = retries.increment(
  File "/Library/Frameworks/Python.framework/Versions/3.9/lib/python3.9/site-packages/urllib3/util/retry.py", line 446, in increment
    raise MaxRetryError(_pool, url, error or ResponseError(cause))
urllib3.exceptions.MaxRetryError: HTTPConnectionPool(host='127.0.0.1', port=9000): Max retries exceeded with url: /jobservice/addjob (Caused by NewConnectionError('<urllib3.connection.HTTPConnection object at 0x7fa1e0083d90>: Failed to establish a new connection: [Errno 61] Connection refused'))

During handling of the above exception, another exception occurred:

Traceback (most recent call last):
  File "/Library/Frameworks/Python.framework/Versions/3.9/lib/python3.9/site-packages/flask/app.py", line 2070, in wsgi_app
    response = self.full_dispatch_request()
  File "/Library/Frameworks/Python.framework/Versions/3.9/lib/python3.9/site-packages/flask/app.py", line 1515, in full_dispatch_request
    rv = self.handle_user_exception(e)
  File "/Library/Frameworks/Python.framework/Versions/3.9/lib/python3.9/site-packages/flask/app.py", line 1513, in full_dispatch_request
    rv = self.dispatch_request()
  File "/Library/Frameworks/Python.framework/Versions/3.9/lib/python3.9/site-packages/flask/app.py", line 1499, in dispatch_request
    return self.ensure_sync(self.view_functions[rule.endpoint])(**req.view_args)
  File "/Users/dgnaneswaran/OneDrive - VMware, Inc/Dina/VM Materials/Take1/Cloud Architect Course works/Cloud Architect Final Project/Recruting-Agency/recruitment-ui-service/webapp/webapp.py", line 66, in managejob
    jobUIService.save_job(
  File "/Users/dgnaneswaran/OneDrive - VMware, Inc/Dina/VM Materials/Take1/Cloud Architect Course works/Cloud Architect Final Project/Recruting-Agency/recruitment-ui-service/webapp/jobUIService.py", line 38, in save_job
    response = requests.post(addJobAPIURL, data, headers=headers)
  File "/Library/Frameworks/Python.framework/Versions/3.9/lib/python3.9/site-packages/requests/api.py", line 119, in post
    return request('post', url, data=data, json=json, **kwargs)
  File "/Library/Frameworks/Python.framework/Versions/3.9/lib/python3.9/site-packages/requests/api.py", line 61, in request
    return session.request(method=method, url=url, **kwargs)
  File "/Library/Frameworks/Python.framework/Versions/3.9/lib/python3.9/site-packages/requests/sessions.py", line 542, in request
    resp = self.send(prep, **send_kwargs)
  File "/Library/Frameworks/Python.framework/Versions/3.9/lib/python3.9/site-packages/requests/sessions.py", line 655, in send
    r = adapter.send(request, **kwargs)
  File "/Library/Frameworks/Python.framework/Versions/3.9/lib/python3.9/site-packages/requests/adapters.py", line 516, in send
    raise ConnectionError(e, request=request)
requests.exceptions.ConnectionError: HTTPConnectionPool(host='127.0.0.1', port=9000): Max retries exceeded with url: /jobservice/addjob (Caused by NewConnectionError('<urllib3.connection.HTTPConnection object at 0x7fa1e0083d90>: Failed to establish a new connection: [Errno 61] Connection refused'))
2021-10-02 16:04:11,471 - werkzeug - INFO - 127.0.0.1 - - [02/Oct/2021 16:04:11] "[35m[1mPOST /addjob HTTP/1.1[0m" 500 -
2021-10-02 16:04:28,040 - werkzeug - INFO - 127.0.0.1 - - [02/Oct/2021 16:04:28] "POST /addjob HTTP/1.1" 200 -
2021-10-02 16:08:03,953 - werkzeug - INFO - 127.0.0.1 - - [02/Oct/2021 16:08:03] "GET /addjob HTTP/1.1" 200 -
